<?xml version="1.0"?>
<robot name="maxon_epos4" xmlns:xacro="http://www.ros.org/wiki/xacro">

  <!-- Base link -->
  <link name="base_link"/>

  <!-- Link1 -->
  <link name="link1_link"/>

  <!-- Joint1 : base_link -> link1_link -->
  <joint name="joint1" type="revolute">
    <parent link="base_link"/>
    <child link="link1_link"/>
    <origin xyz="0 0 0" rpy="0 0 0"/>
    <axis xyz="1 0 0"/>
    <dynamics damping="0.7"/>
    <limit effort="100.0" velocity="1300" lower="${-pi}" upper="${pi}"/>
  </joint>

  <!-- Link2 -->
  <link name="link2_link"/>

  <!-- Joint2 : link1_link -> link2_link -->
  <joint name="joint2" type="revolute">
    <parent link="link1_link"/>
    <child link="link2_link"/>
    <origin xyz="0 0 0" rpy="0 0 0"/>
    <axis xyz="1 0 0"/>
    <dynamics damping="0.7"/>
    <limit effort="100.0" velocity="1300" lower="${-pi}" upper="${pi}"/>
  </joint>

  <!-- Link3 -->
  <link name="link3_link"/>

  <!-- Joint3 : link2_link -> link3_link -->
  <joint name="joint3" type="revolute">
    <parent link="link2_link"/>
    <child link="link3_link"/>
    <origin xyz="0 0 0" rpy="0 0 0"/>
    <axis xyz="1 0 0"/>
    <dynamics damping="0.7"/>
    <limit effort="100.0" velocity="1300" lower="${-pi}" upper="${pi}"/>
  </joint>

  <!-- Link4 -->
  <link name="link4_link"/>

  <!-- Joint4 : link3_link -> link4_link -->
  <joint name="joint4" type="revolute">
    <parent link="link3_link"/>
    <child link="link4_link"/>
    <origin xyz="0 0 0" rpy="0 0 0"/>
    <axis xyz="1 0 0"/>
    <dynamics damping="0.7"/>
    <limit effort="100.0" velocity="1300" lower="${-pi}" upper="${pi}"/>
  </joint>

  <!-- Transmissions -->

  <transmission name="transmission_joint1">
    <type>transmission_interface/SimpleTransmission</type>
    <joint name="joint1">
      <hardwareInterface>hardware_interface/EffortJointInterface</hardwareInterface>
    </joint>
    <actuator name="motor_joint1">
      <hardwareInterface>EffortJointInterface</hardwareInterface>
      <mechanicalReduction>26</mechanicalReduction>
    </actuator>
  </transmission>

  <transmission name="transmission_joint2">
    <type>transmission_interface/SimpleTransmission</type>
    <joint name="joint2">
      <hardwareInterface>hardware_interface/EffortJointInterface</hardwareInterface>
    </joint>
    <actuator name="motor_joint2">
      <hardwareInterface>EffortJointInterface</hardwareInterface>
      <mechanicalReduction>26</mechanicalReduction>
    </actuator>
  </transmission>

  <transmission name="transmission_joint3">
    <type>transmission_interface/SimpleTransmission</type>
    <joint name="joint3">
      <hardwareInterface>hardware_interface/EffortJointInterface</hardwareInterface>
    </joint>
    <actuator name="motor_joint3">
      <hardwareInterface>EffortJointInterface</hardwareInterface>
      <mechanicalReduction>26</mechanicalReduction>
    </actuator>
  </transmission>

  <transmission name="transmission_joint4">
    <type>transmission_interface/SimpleTransmission</type>
    <joint name="joint4">
      <hardwareInterface>hardware_interface/EffortJointInterface</hardwareInterface>
    </joint>
    <actuator name="motor_joint4">
      <hardwareInterface>EffortJointInterface</hardwareInterface>
      <mechanicalReduction>26</mechanicalReduction>
    </actuator>
  </transmission>

</robot>
